Workbook
Name arrêt_prévu__sans_prol: [1]evo_reacteur!$D$1:$D$121
Name Base: #REF!
Name Base3: [2]REACTORSWNISR2019!$A$1:$BD$789
Name Col_Age: [2]REACTORSWNISR2019!$AP$2:$AP$1048576
Name col_consCanc: [2]DATA_CancSusp!$F:$F
Name col_consResume: [2]DATA_CancSusp!$I:$I
Name col_consSusp: [2]DATA_CancSusp!$H:$H
Name col_ConsYear_2018Plus: [2]REACTORSWNISR2019!$O:$O
Name Col_Country: [2]REACTORSWNISR2019!$D$2:$D$1048576
Name col_Country_2018Plus: [2]REACTORSWNISR2019!$D:$D
Name Col_OperatingAge: [2]REACTORSWNISR2019!$AN$2:$AN$1048576
Name Col_Region_2018Plus: [2]REACTORSWNISR2019!$C:$C
Name Col_ShutAge: [2]REACTORSWNISR2019!$AQ:$AQ
Name col_ShutDownYear: [2]REACTORSWNISR2019!$AA:$AA
Name Col_StartUpYear_2018Plus: [2]REACTORSWNISR2019!$X:$X
Name Col_Status_2018Plus: [2]REACTORSWNISR2019!$F:$F
Name ConstructionCanc_Susp: [2]DATA_CancSusp!$A$4:$I$110
Name Country: [3]codes!$D$3:$D$38
Name GEO: [3]codes!$A$2:$A$9
Name OCC_COL: 'Specific OCC in $ per kW 2018 '!$S:$S
Name Reactors_Years_IAEA2021: [2]DATAReactors_Years!$AJ:$AJ
Name Reactors_Years_Reference_unit_power: [2]DATAReactors_Years!$AN:$AN
Name Reactors_Years_WNISR2021: [2]DATAReactors_Years!$V:$V
Name Reactors_Years_Year: [2]DATAReactors_Years!$F:$F
Name Reactors_Years2_Country: [2]DATAReactors_Years2021!$C:$C
Name Reactors_Years2_Reference_unit_power: [2]DATAReactors_Years2021!$AN:$AN
Name Reactors_Years2_WNISR2022: [2]DATAReactors_Years2021!$V:$V
Name Reactors_Years2_Year: [2]DATAReactors_Years2021!$F:$F
Name reactorssss: '[4]REACTORS.XLS'!$A$2:$BS$750
Name Tableau: #REF!

Sheet Table for Thesis
A2: Reactor | B2: Confinement Type | C2: Reactor Type | D2: Capacity [MW] | E2: Cost Type | F2: Readiness | G2: Relative/Absolute | H2: Value | I2: Unit | J2: Cost Reference Year | K2: Availability/Capacity Factor | L2: Comment | M2: Reference | N2: Operational Mode | O2: Contingency
A3: LIFE1 | B3: Inertia | C3: Indirect Drive | D3: 400 | E3: Capital Cost | F3: FOAK | G3: Absolute | H3: 6000000000 | I3: USD | J3: 2011 | K3: AV: 0.5 | L3: Learning rates based on experiences from NIF but not further specified | M3: Anklam et al. (2011) | N3: Steady-State (possible due to high repetition rate of laser pulses (nearly 15 per second)) | O3: -
A4: LIFE2 | B4: Inertia | C4: Indirect Drive | D4: 2200 | E4: Capital Cost | F4: NOAK | G4: Absolute | H4: 5000000000 | I4: USD | J4: 2011 | K4: AV: 0.92 | L4: Average value between 4 and 6 billion USD; Learning rates based on experiences from NIF but not further specified | M4: Anklam et al. (2011) | N4: Steady-State (possible due to high repetition rate of laser pulses (nearly 15 per second)) | O4: -
A5: LIFE3 | B5: Inertia | C5: Indirect Drive | D5: 2660 | E5: Capital Cost | F5: 10th-OAK | G5: Absolute | H5: 4000000000 | I5: USD | J5: 2011 | K5: AV: 0.92 | L5: Learning rates based on experiences from NIF but not further specified | M5: Anklam et al. (2011) | N5: Steady-State (possible due to high repetition rate of laser pulses (nearly 15 per second)) | O5: -
A6: UWMAK-III | B6: Magnetic | C6: Tokamak | D6: 1985 | E6: OCC | F6: 10th-OAK | G6: Absolute | H6: 3270000000 | I6: USD | J6: 1975 | K6: AV: 0.95 | M6: Badger et al. (1975) | N6: Pulsed but TES integrated for steady-state operation | O6: 980000000
A7: n.a. | B7: Magnetic | C7: Tokamak | D7: 1500 | E7: LCOE | F7: NOAK | G7: Relative | H7: 66.7 | I7: EUR/MWh | J7: 2011 | K7: AV: 0.8 | L7: Pessimistic scenario A; 40 years lifetime; 2060-2070; 10 years construction time | M7: Bednyagin & Gnansounou (2011)
A8: n.a. | B8: Magnetic | C8: Tokamak | D8: 1500 | E8: LCOE | F8: FOAK | G8: Relative | H8: 78.4 | I8: EUR/MWh | J8: 2011 | K8: CF: 0.8 | L8: Pessimistic scenario A; 40 years lifetime; 2060-2070; 10 years construction time | M8: Bednyagin & Gnansounou (2011) | N8: Steady-State | O8: -
A9: n.a. | B9: Magnetic | C9: Tokamak | D9: 1500 | E9: LCOE | F9: FOAK | G9: Relative | H9: 64.5 | I9: EUR/MWh | J9: 2011 | K9: CF: 0.8 | L9: Scenario B; 40 years litetim; 2050-2060; 10 years construction time | M9: Bednyagin & Gnansounou (2011) | N9: Steady-State | O9: -
A10: n.a. | B10: Magnetic | C10: Tokamak | D10: 1500 | E10: LCOE | F10: 10th-OAK | G10: Relative | H10: 61.1 | I10: EUR/MWh | J10: 2011 | K10: CF: 0.8 | L10: Pessimistic scenario A; 40 years lifetime; 2060-2070; 10 years construction time | M10: Bednyagin & Gnansounou (2011) | N10: Steady-State | O10: -
A11: n.a. | B11: Magnetic | C11: Tokamak | D11: 1500 | E11: LCOE | F11: 10th-OAK | G11: Relative | H11: 49.3 | I11: EUR/MWh | J11: 2011 | K11: CF: 0.8 | L11: Scenario B; 40 years litetim; 2050-2060; 10 years construction time | M11: Bednyagin & Gnansounou (2011) | N11: Steady-State | O11: -
A12: n.a. | B12: Magnetic | C12: Tokamak | D12: 1500 | E12: LCOE | F12: FOAK | G12: Relative | H12: 51.3 | I12: EUR/MWh | J12: 2011 | K12: CF: 0.8 | L12: Optimistic scenario C; 40 years litetim; 2050-2060; 10 years construction time | M12: Bednyagin & Gnansounou (2011) | N12: Steady-State | O12: -
A13: n.a. | B13: Magnetic | C13: Tokamak | D13: 1500 | E13: LCOE | F13: 10th-OAK | G13: Relative | H13: 39.4 | I13: EUR/MWh | J13: 2011 | K13: CF: 0.8 | L13: Optimistic scenario C; 40 years litetim; 2050-2060; 10 years construction time | M13: Bednyagin & Gnansounou (2011) | N13: Steady-State | O13: -
A14: n.a. | B14: Magnetic | C14: Tokamak | D14: 1500 | E14: LCOE | F14: Advanced NOAK | G14: Relative | H14: 36.4 | I14: EUR/MWh | J14: 2011 | K14: CF: 0.8 | L14: Optimistic scenario C; 40 years litetim; 2050-2060; 10 years construction time | M14: Bednyagin & Gnansounou (2011)
A15: n.a. | B15: Magnetic | C15: Tokamak | D15: 1500 | E15: LCOE | F15: Highly Advanced NOAK | G15: Relative | H15: 54.6 | I15: EUR/MWh | J15: 2011 | K15: CF: 0.8 | L15: Pessimistic scenario A; 40 years lifetime; 2060-2070; 10 years construction time | M15: Bednyagin & Gnansounou (2011) | N15: Steady-State | O15: -
A16: n.a. | B16: Magnetic | C16: Tokamak | D16: 1500 | E16: LCOE | F16: Highly Advanced NOAK | G16: Relative | H16: 42.9 | I16: EUR/MWh | J16: 2011 | K16: CF: 0.8 | L16: Scenario B; 40 years litetim; 2050-2060; 10 years construction time | M16: Bednyagin & Gnansounou (2011) | N16: Steady-State | O16: -
A17: n.a. | B17: Magnetic | C17: Tokamak | D17: 1500 | E17: LCOE | F17: Highly Advanced NOAK | G17: Relative | H17: 34.3 | I17: EUR/MWh | J17: 2011 | K17: CF: 0.8 | L17: Optimistic scenario C; 40 years litetim; 2050-2060; 10 years construction time | M17: Bednyagin & Gnansounou (2011) | N17: Steady-State | O17: -
A18: n.a. | B18: Magnetic | C18: Tokamak | D18: 1500 | E18: OCC | F18: FOAK | G18: Relative | H18: 8000 | I18: EUR/kW | J18: 2011 | K18: CF: 0.8 | L18: 40 years lifetime; 10 years construction time | M18: Bednyagin & Gnansounou (2011) | N18: Steady-State | O18: - | R18: Reactor | S18: Confinement type | T18: Reactor type | U18: Capacity [MW] | V18: Cost type | W18: Readiness | X18: Value | Y18: Unit | Z18: Cost base year | AA18: Comment | AB18: Reference
A19: MARS | B19: Magnetic | C19: Magnetic Mirror | D19: 1198 | E19: OCC | F19: 10th-OAK | G19: Absolute | H19: 4969000000 | I19: USD | J19: 1985 | K19: AV: 0.7 | L19: 6 years construction time | M19: Berwald et al. (1987) | N19: Steady-State | O19: 436000000 | R19: UWMAK-III | S19: Magnetic | T19: Tokamak | U19: 1985 | V19: OCC | W19: 10th-OAK | X19: 3270000000 | Y19: USD | Z19: 1975 | AB19: Badger et al. (1975)
A20: HYLIFE-I (single unit) | B20: Inertia | C20: Direct Drive | D20: 1010 | E20: OCC | F20: 10th-OAK | G20: Absolute | H20: 552000000 | I20: USD | J20: 1983 | K20: AV: 0.7 | L20: 30 years lifetime; 8 years construction time | M20: Blink et al. (1985) | N20: Steady State (due to high repetition rate of pulses) | O20: 328000000 | R20: n.a. | S20: Magnetic | T20: Tokamak | U20: 1500 | V20: OCC | W20: FOAK | X20: 8000 | Y20: EUR/kW | Z20: 2011 | AA20: 40 years lifetime; 10 years construction time | AB20: Bednyagin & Gnansounou (2011)
A21: n.a. | B21: Magnetic | C21: Tokamak | D21: 1500 | E21: LCOE | F21: NOAK | G21: Relative | H21: 54.8 | I21: EUR/MWh | J21: 2011 | L21: Scenario B; 40 years litetim; 2050-2060; 10 years construction time | M21: Bednyagin & Gnansounou (2011) | R21: MARS | S21: Magnetic | T21: Magnetic Mirror | U21: 1198 | V21: OCC | W21: 10th-OAK | X21: 4969000000 | Y21: USD | Z21: 1985 | AA21: 6 years construction time | AB21: Berwald et al. (1987)
A22: n.a. | B22: Magnetic | C22: Tokamak | D22: 1500 | E22: LCOE | F22: NOAK | G22: Relative | H22: 43.6 | I22: EUR/MWh | J22: 2011 | L22: Optimistic scenario C; 40 years litetim; 2050-2060; 10 years construction time | M22: Bednyagin & Gnansounou (2011) | R22: HYLIFE-I (single unit) | S22: Inertia | T22: Direct Drive | U22: 1010 | V22: OCC | W22: 10th-OAK | X22: 552000000 | Y22: USD | Z22: 1983 | AA22: 30 years lifetime; 8 years construction time | AB22: Blink et al. (1985)
A23: n.a. | B23: Magnetic | C23: Tokamak | D23: 1500 | E23: LCOE | F23: Advanced NOAK | G23: Relative | H23: 57.3 | I23: EUR/MWh | J23: 2011 | L23: Scenario B; 40 years litetim; 2050-2060; 10 years construction time | M23: Bednyagin & Gnansounou (2011) | R23: HYLIFE-I (dual unit) | S23: Inertia | T23: Direct Drive | U23: 2000 | V23: OCC | W23: 10th-OAK | X23: 855000000 | Y23: USD | Z23: 1983 | AA23: Dual-unit | AB23: Blink et al. (1985)
A24: n.a. | B24: Magnetic | C24: Tokamak | D24: 1500 | E24: LCOE | F24: Advanced NOAK | G24: Relative | H24: 45.6 | I24: EUR/MWh | J24: 2011 | L24: Optimistic scenario C; 40 years litetim; 2050-2060; 10 years construction time | M24: Bednyagin & Gnansounou (2011) | R24: STARFIRE | S24: Magnetic | T24: Tokamak | U24: 1200 | V24: OCC | W24: 10th-OAK | X24: 1.93553e+09 | Y24: USD | Z24: 1980 | AA24: 30 years lifetime; 6 years construction time | AB24: C.C. Baker et al. (1980)
A25: ARIES-I | B25: Magnetic | C25: Advanced Tokamak | D25: 1000 | E25: COE | F25: 10th-OAK | G25: Relative | H25: 100 | I25: mills/kWh | J25: 1992 | K25: - | M25: Najmabadi et al. (2006) | N25: - | O25: - | R25: V-Li/TOK (level safety assurance = 4) | S25: Magnetic | T25: Tokamak | U25: 1200 | V25: OCC | W25: 10th-OAK | X25: 2853000000 | Y25: USD | Z25: 1990 | AA25: Plant startup: 2025; 6 years construction time; 30 years lifetime | AB25: Delene (1991)
A26: ARIES-I (High-Field) | B26: Magnetic | C26: Advanced Tokamak | D26: 1000 | E26: COE | F26: 10th-OAK | G26: Relative | H26: 82 | I26: mills/kWh | J26: 1992 | K26: - | M26: Najmabadi et al. (2006) | N26: - | O26: - | R26: V-Li/TOK (level safety assurance = 3) | S26: Magnetic | T26: Tokamak | U26: 1200 | V26: OCC | W26: 10th-OAK | X26: 2547000000 | Y26: USD | Z26: 1990 | AA26: Plant startup: 2025; 6 years construction time; 30 years lifetime | AB26: Delene (1991)
A27: HYLIFE-I (dual unit) | B27: Inertia | C27: Direct Drive | D27: 2000 | E27: OCC | F27: 10th-OAK | G27: Absolute | H27: 855000000 | I27: USD | J27: 1983 | K27: AV: 0.7 | L27: Dual-unit | M27: Blink et al. (1985) | N27: Steady State (due to high repetition rate of pulses) | O27: 508000000 | R27: ARIES-I | S27: Magnetic | T27: Tokamak | U27: 1200 | V27: OCC | W27: 10th-OAK | X27: 4092000000 | Y27: USD | Z27: 1990 | AA27: Plant startup: 2025; 6 years construction time; 30 years lifetime | AB27: Delene (1991)
A28: STARFIRE | B28: Magnetic | C28: Tokamak | D28: 1200 | E28: OCC | F28: 10th-OAK | G28: Absolute | H28: 1.93553e+09 | I28: USD | J28: 1980 | K28: AV: 0.75 | L28: 30 years lifetime; 6 years construction time | M28: C.C. Baker et al. (1980) | N28: Steady-State with load-following ability: "Once operating, the reactor has the ability to load-follow at a rate of 5% of rated power increase or decrease per minute, although the reactor is designed as a base load unit" | O28: 188040000 | R28: Generomak - ESECOM - RAF-LiPb/RFP | S28: Magnetic | T28: Reversed-Field Pinch | U28: 1200 | V28: OCC | W28: 10th-OAK | X28: 1566300000 | Y28: USD | Z28: 1986 | AA28: 6 years construction time; 30 years lifetime | AB28: Delene et al. (1988)
A29: Modular Fusion Plant | B29: Magnetic | C29: Spherical Tokamak | D29: 735.77 | E29: COE | F29: FOAK | G29: Relative | H29: 0.06 | I29: USD/kWh | J29: 2009 | K29: CF. 0.95 | L29: Modular plant; learning effects due to mass prodction for modular parts | M29: Chuyanov et al. (2017) | N29: Steady-State | O29: - | R29: Generomak - ESECOM - V-Li/RFP | S29: Magnetic | T29: Reversed-Field Pinch | U29: 1200 | V29: OCC | W29: 10th-OAK | X29: 1589200000 | Y29: USD | Z29: 1986 | AA29: 6 years construction time; 30 years lifetime | AB29: Delene et al. (1988)
A30: CFETR (Full Superconducting Tokamak) | B30: Magnetic | C30: Tokamak | D30: 121.1 | E30: OCC | F30: FOAK | G30: Absolute | H30: 2579400000 | I30: USD | J30: 2009 | K30: Target: > 0.3-0.5 burning time | L30: Experimental; Without net electricity for output and needs external power supply | M30: Chen et al. (2015) | N30: Pulsed | O30: 434600000 | R30: ARIES-RS | S30: Magnetic | T30: Tokamak | U30: 1000 | V30: OCC | W30: 10th-OAK | X30: 3521500000 | Y30: USD | Z30: 1999 | AA30: 6 years construction time; 30 years lifetime | AB30: Delene et al. (2001)
A31: CFETR (Water-cooling Cu magnets) | B31: Magnetic | C31: Tokamak | D31: 121.1 | E31: OCC | F31: FOAK | G31: Absolute | H31: 1414500000 | I31: USD | J31: 2009 | K31: Target: > 0.3-0.5 burning time | L31: Experimental; Without net electricity for output and needs external power supply | M31: Chen et al. (2015) | N31: Pulsed | O31: 238300000 | R31: ARIES-ST | S31: Magnetic | T31: Tokamak | U31: 1000 | V31: OCC | W31: 10th-OAK | X31: 3880800000 | Y31: USD | Z31: 1999 | AA31: 6 years construction time; 30 years lifetime | AB31: Delene et al. (2001)
A32: V-Li/TOK (level safety assurance = 4) | B32: Magnetic | C32: Tokamak | D32: 1200 | E32: OCC | F32: 10th-OAK | G32: Absolute | H32: 2853000000 | I32: USD | J32: 1990 | K32: CF: 0.75 | L32: Plant startup: 2025; 6 years construction time; 30 years lifetime | M32: Delene (1991) | N32: Steady-State | O32: 557000000 | R32: Base Case Heliotron | S32: Magnetic | T32: Heliotron | U32: 1940 | V32: OCC | W32: NOAK | X32: 5767800000 | Y32: USD | Z32: 2003 | AB32: Dolan et al. (2005)
A33: V-Li/TOK (level safety assurance = 3) | B33: Magnetic | C33: Tokamak | D33: 1200 | E33: OCC | F33: 10th-OAK | G33: Absolute | H33: 2547000000 | I33: USD | J33: 1990 | K33: CF: 0.75 | L33: Plant startup: 2025; 6 years construction time; 30 years lifetime | M33: Delene (1991) | N33: Steady-State | O33: 469000000 | R33: New ARIES | S33: Magnetic | T33: Tokamak | U33: 1000 | V33: OCC | W33: 10th-OAK | X33: 2105150000 | Y33: USD | Z33: 1992 | AB33: Dragojlovic et al. (2010)
A34: ARIES-I | B34: Magnetic | C34: Tokamak | D34: 1200 | E34: OCC | F34: 10th-OAK | G34: Absolute | H34: 4092000000 | I34: USD | J34: 1990 | K34: CF: 0.75 | L34: Plant startup: 2025; 6 years construction time; 30 years lifetime | M34: Delene (1991) | N34: Steady-State | O34: 636000000 | R34: DEMO2 | S34: Magnetic | T34: Tokamak | U34: 953 | V34: OCC | W34: FOAK | X34: 7516000000 | Y34: USD | Z34: 2015 | AA34: 40 years lifetime; discount rate: 7%; 10 years construction time | AB34: Entler et al. (2018)
A35: STARFIRE | B35: Magnetic | C35: Tokamak | D35: 1200 | E35: Fuel Cost | F35: 10th-OAK | G35: Relative | H35: 0.04 | I35: mills/kWh | J35: 1980 | K35: - | M35: C.C. Baker et al. (1980) | N35: - | O35: - | R35: Fusion Power Corporation Reactor (incl. Hydrogen production) | S35: Inertia | T35: Ion Beam Driver | U35: 38000 | V35: OCC | W35: NOAK | X35: 75244000000 | Y35: USD | Z35: 2014 | AA35: Including hydrogen production | AB35: Helsley and Burke (2014)
A36: Generomak - ESECOM - V-LI/TOK | B36: Magnetic | C36: Tokamak | D36: 1200 | E36: Fuel Cost | F36: 10th-OAK | G36: Relative | H36: 0.35563751 | I36: USD/MWh | J36: 1986 | K36: - | M36: Delene et al. (1988) | N36: - | O36: - | R36: CREST | S36: Magnetic | T36: Tokamak | U36: 1160 | V36: OCC | W36: FOAK | X36: 7980000 | Y36: USD/MW | Z36: 2019 | AB36: Hiwatari and Goto (2019)
A37: Generomak - ESECOM - RAF-He/TOK | B37: Magnetic | C37: Tokamak | D37: 1200 | E37: Fuel Cost | F37: 10th-OAK | G37: Relative | H37: 0.35563751 | I37: USD/MWh | J37: 1986 | K37: - | M37: Delene et al. (1988) | N37: - | O37: - | R37: CREST | S37: Magnetic | T37: Tokamak | U37: 1160 | V37: OCC | W37: 10th-OAK | X37: 6870000 | Y37: USD/MW | Z37: 2019 | AB37: Hiwatari and Goto (2019)
A38: Generomak - ESECOM - RAF-LiPb/RFP | B38: Magnetic | C38: Reversed-Field Pinch | D38: 1200 | E38: Fuel Cost | F38: 10th-OAK | G38: Relative | H38: 0.35563751 | I38: USD/MWh | J38: 1986 | K38: - | M38: Delene et al. (1988) | N38: - | O38: - | R38: FPP_low | S38: Magneto-Inertial | T38: Stabilized Liner Compressor / Plasma Jet Driven Magneto-Inertial Fusion / Staged Z-Pinch / Sheared Flow Stabilized Z-Pinch | U38: 383.1 | V38: OCC | W38: Advanced NOAK | X38: 7.998e+08 | Y38: USD | Z38: 2020 | AA38: Four different fusion technologies: Stabilized Liner Compressor, Plansa Jet Driven Magneto-Intertial Fusion, Staged Z-Pinch, Sheared Flow Stabilized Z-Pinch; 6 years construction time | AB38: Hsu et al. (2020)
A39: Generomak - ESECOM - V-Li/RFP | B39: Magnetic | C39: Reversed-Field Pinch | D39: 1200 | E39: Fuel Cost | F39: 10th-OAK | G39: Relative | H39: 0.35563751 | I39: USD/MWh | J39: 1986 | K39: - | M39: Delene et al. (1988) | N39: - | O39: - | R39: FPP_high | S39: Magneto-Inertial | T39: Stabilized Liner Compressor / Plasma Jet Driven Magneto-Inertial Fusion / Staged Z-Pinch / Sheared Flow Stabilized Z-Pinch | U39: 814.4 | V39: OCC | W39: Advanced NOAK | X39: 1572000000 | Y39: USD | Z39: 2020 | AA39: Four different fusion technologies: Stabilized Liner Compressor, Plansa Jet Driven Magneto-Intertial Fusion, Staged Z-Pinch, Sheared Flow Stabilized Z-Pinch; 6 years construction time | AB39: Hsu et al. (2020)
A40: Generomak - ESECOM - SiC-He/TOK | B40: Magnetic | C40: Tokamak | D40: 1200 | E40: Fuel Cost | F40: 10th-OAK | G40: Relative | H40: 0.35563751 | I40: USD/MWh | J40: 1986 | K40: - | M40: Delene et al. (1988) | N40: - | O40: - | R40: Large Helical Device | S40: Magnetic | T40: Heliotron | U40: 1604 | V40: OCC | W40: NOAK | X40: 7270000000 | Y40: USD | Z40: 2002 | AA40: 40 years lifetime; discount rate: 3% | AB40: Kozaki et al. (2009)
A41: Generomak - ESECOM - V-FLiBe/TOK | B41: Magnetic | C41: Tokamak | D41: 1200 | E41: Fuel Cost | F41: 10th-OAK | G41: Relative | H41: 0.35563751 | I41: USD/MWh | J41: 1986 | K41: - | M41: Delene et al. (1988) | N41: - | O41: - | R41: Large Helical Device | S41: Magnetic | T41: Heliotron | U41: 1601 | V41: OCC | W41: NOAK | X41: 7393000000 | Y41: USD | Z41: 2002 | AA41: 40 years lifetime; discount rate: 3% | AB41: Kozaki et al. (2009)
...

Sheet Cost data collection_clean
A2: As found in literature | W2: Prometheus: https://aries.pppl.gov/LIB/REPORT/OTHER/PROMETHEUS/appc.pdf | AS2: Tritium Plant Capital Cost
A3: No. | B3: Reactor | C3: Confinement Type | D3: Reactor Type | E3: Capacity [MW] | F3: Cost Type | G3: Readiness | H3: Relative/Absolute | I3: Value | J3: Unit | K3: Year | L3: Reference | M3: Study Type | N3: Source Type | O3: Comment | P3: Availability/Capacity Factor/Plasma Duration | Q3: Operational Mode | R3: Initial Tritium | S3: Contingency | T3: Decomissioning Costs/year | V3: Notes | W3: Questions & Answers to Assumptions | X3: Comparison with other Technologies | Y3: Cost Shares OCC | AE3: To be discussed | AF3: Summary (short) | AG3: Summary | AH3: Step by Step Paper Content | AI3: Most significant cost influences (short) | AJ3: Most significant cost influences | AK3: Further Cost Parameters & Assumptions (short) | AL3: Further Cost Parameters & Assumptions | AM3: Questions & Answers (short) | AN3: Questions & Answers
A4: 1 | B4: LIFE1 | C4: Inertia | D4: Indirect Drive | E4: 400 | F4: Capital Cost | G4: FOAK | H4: Absolute | I4: 6000000000 | J4: USD | K4: 2011 | L4: Anklam et al. (2011) | O4: Learning rates based on experiences from NIF but not further specified | P4: 0.5 | Q4: Steady-State (possible due to high repetition rate of laser pulses (nearly 15 per second)) | R4: - | S4: - | T4: - | V4: Monte Carlo applied 'Readiness asssumed | W4: 1. Welche Modellannahmen werden getroffen? Die LIFE-Studie trifft mehrere Modellannahmen, die darauf abzielen, ein kommerziell attraktives und reifes Fusionskraftwerk zu konzipieren: • Konzept und Technologiebasis: Das LIFE-Konzept konzentriert sich ausschließlich auf die reine Fusion und nutzt dabei die Wissenschaft und Technologie der National Ignition Facility (NIF). Dies umfasst die grundlegende Lasertechnologie (Neodym-dotierte Glas-Gain-Medien, Multipass-Architektur mit Spatial Filtering) und die Target-Physik (indirekt angetriebene Hot-Spot-Zündung). • Laserdesign und Betrieb: Das Laserdesign wird für den Kraftwerksbetrieb modifiziert, um eine kompaktere, modulare Laserarchitektur für hohe Verfügbarkeit, aktives thermisches Management für höhere Wiederholungsraten (10 bis 20 Hz) und Diodenpumpen für eine höhere Lasereffizienz (~10 % bis 20 %) zu ermöglichen. • Fusionsziele (Targets): Es wird angenommen, dass massenhaft herstellbare Fusionsziele verfügbar sind. • Phasen des Kommerzialisierungspfads: Der Pfad wird durch drei "Point Designs" beschrieben: ◦ LIFE.1: Soll 400 MW Fusionsleistung produzieren und ist darauf ausgelegt, bestehende Materialien und Technologien maximal zu nutzen. Es wird als Testbett dienen, um die erforderlichen Betriebsverfahren für ein kommerzielles Kraftwerk zu demonstrieren und Materialien sowie Prozesse in einer kontinuierlichen Fusionsumgebung zu qualifizieren. Die Inbetriebnahme wird innerhalb von 10 bis 15 Jahren nach NIF-Zündung angestrebt. Materialien werden mittels eines beschleunigten Testschemas mit höherer Strahlenschädigungsrate getestet. ◦ LIFE.2: Ein 1 GWe kommerzielles Kraftwerk, das entweder eine Neuanlage oder eine Leistungssteigerung von LIFE.1 sein könnte. Es nutzt die gleiche Lasertechnologie wie LIFE.1, jedoch fortschrittlichere, strahlungsbeständige Strukturmaterialien (Oxid-Dispersions-gehärteter Stahl – ODS-Stahl), um höhere Temperaturen und Leistungsdichten zu ermöglichen. ◦ LIFE.3: Repräsentiert eine reife LIFE-Technologie mit weiteren Verbesserungen in der Zieleffizienz, niedrigeren Fusionszielkosten und höheren Betriebstemperaturen. • Betriebsparameter (Tabelle I): Detaillierte Annahmen für die drei Point Designs umfassen: ◦ Laserenergie (1.3 MJ bis 2.4 MJ) ◦ Wiederholungsrate (konstant 14.8 Hz) ◦ Elektrischer Nettogewinn der Anlage (1.3 bis 7.0) ◦ Eigenstrombedarf (House Power Fraction: 0.77 bis 0.16) ◦ Thermodynamischer Wirkungsgrad (Thermal to Electric Efficiency: 43% bis 53%) ◦ Erste Wand-Material und Radius (LIFE.1: RAFMS, 3.7 m; LIFE.2/3: ODS-Stahl, 5.6 m / 6.2 m) ◦ Erste Wand-Neutronenlast und Lebensdauer (LIFE.1: 1.9 MW/m², 0.9 Jahre; LIFE.2/3: 4.5 MW/m², 4.5 Jahre) ◦ Fusionsausbeute und Target-Gewinn (27 MJ / Gain 21 bis 180 MJ / Gain 94) ◦ Fusionsleistung (400 MW bis 2660 MW) ◦ Verfügbarkeitsallokation (LIFE.1: 50%; LIFE.2/3: 92%). • Regulierungsrahmen: LIFE.1 und LIFE.2 werden voraussichtlich NRC-lizenziert sein, wobei LIFE.1 optional unter einer DOE-Autorisierungsbasis betrieben werden könnte. • Markteinführungszeitpunkt: Es besteht eine starke Motivation, die Kommerzialisierung bis 2030 oder früher zu erreichen, um am Ersatz veralteter Kraftwerke teilzuhaben. 2. Welche Modell- und Kostenannahmen basieren auf tatsächlichen Erfahrungswerten und welche nur Schätzungen oder Prognosen? Welche Annahmen stammen woher? Die Annahmen in der LIFE-Studie sind eine Mischung aus der Nutzung bestehender Erfahrungen und notwendigen Prognosen für eine zukünftige, noch zu entwickelnde Technologie: Modellannahmen: Basierend auf Erfahrungswerten und bestehenden Daten: • NIF-Technologie: Das Konzept nutzt die Wissenschaft und Technologie, die an der National Ignition Facility (NIF) demonstriert wird. Dies umfasst die Lasertechnologie und Target-Physik. Die NIF dient als Referenzpunkt für die Machbarkeit der grundlegenden Laser- und Fusionsprozesse. • Planung und Zeitpläne: Die Dauern für Design und Bau sind durch "previous experience in building the NIF and other large capital projects" informiert. • Marktwachstum und Anlagenlebensdauer: Die Nachfrageentwicklung in den USA wird durch Extrapolation der EIA-Prognosen bis 2100 (mit 50 % Elektrifizierung des Transportsektors bis 2050) berechnet [3, Ref. 1]. Die Annahmen für die Lebensdauer bestehender Kraftwerke (80 Jahre für Kohle/Nuklear, 60 Jahre für Erdgas) basieren ebenfalls auf Erfahrungswerten. Schätzungen oder Prognosen: • "Tenth-of-a-Kind"-Anlage: Die Annahme einer 92%igen Verfügbarkeit für eine "10th of a kind plant" (zehnte Anlage dieser Art) ist eine Prognose für den Reifegrad der modularen Architektur. Für LIFE.1 ist eine geringere Verfügbarkeit von 50% angesetzt, was dem Charakter einer Demonstrationsanlage entspricht. • Materialqualifizierung: Die Qualifizierung von ODS-Stahl (Oxid-Dispersions-gehärteter Stahl) für höhere Temperaturen und Strahlungsbeständigkeit in LIFE.1 ist eine Prognose, die durch das Testbett in LIFE.1 erreicht werden soll. • Zukünftige Effizienzsteigerungen: Für LIFE.3 werden "additional improvements in target efficiency, lower fusion target costs and higher operating temperatures" projiziert. • Marktdurchdringung: Die Rate der Marktdurchdringung von Fusion ist eine Prognose, die durch die Nachfrage und den Hochlauf der Lieferkette (Verdoppelung der Kapazität alle 5 oder 10 Jahre) begrenzt wird. • Vorteile der Frühkommerzialisierung: Die Quantifizierung von vermiedenen CO2-Emissionen (100-140 GT), hochradioaktivem Atommüll (230.000-360.000 MT) und Plutonium (3000-4000 MT) bis 2100 sind Prognosen basierend auf spezifischen Szenarien, in denen Fusion Kohle- oder Spaltanlagen ersetzt. • Kommerzialisierungszeitplan: Der Zeitplan von "roughly 12 years from project start" bis zur ersten Pilotanlage ist eine Prognose. Kostenannahmen: Basierend auf Erfahrungswerten und bestehenden Daten: • Lasersystemkosten: Werden mit einer Bottom-up-Methodik geschätzt, wobei die Einheitskosten aus Lieferantenangeboten und Daten des NIF-Projekts abgeleitet werden. • Kosten für Fusionsreaktor, Tritiumanlage und Energieumwandlungssysteme: Werden aus Studien in der Literatur entnommen (Refs. 6-10) und auf den LIFE-Betriebspunkt skaliert. ◦ Referenz 6: "Nuclear Energy Cost Data Base" für Kern- und Kohlekraftwerke. ◦ Referenz 7: "US Advanced Liquid Metal Reactor Program - Actinide Recycle Systems: 1994 Capital and Busbar Cost Estimates". ◦ Referenzen 8, 9, 10: IFE-Kraftwerksdesign-Studien (Osiris, Sombrero, Prometheus). • Kosten für Fusionsziele: Abgeleitet aus einer Studie zur Zielherstellung (Ref. 11: R. Miles, "LIFE Target Fabrication Costs," LLNL report LLNL-TR-416932 (2009)). • Indirekte Kostenfaktoren: Stammen aus den Gen IV-Kostenabschätzungsrichtlinien (Ref. 13: OECD report GIF/EMWG/2007/004 (2007)). • Kapital- und indirekte Kostendifferenziale (nukleare vs. konventionelle Systeme): Stammen aus einer General Atomic-Studie (Ref. 14: R. M. Bourque, "Fusion Reactor Cost Reductions by Employing Non-Nuclear Grade Components," 1987). • Stromgestehungskosten (COE): Berechnet unter Verwendung der Discounted Cash Flow-Methodik, wie im MIT-Bericht von 2009 beschrieben (Ref. 12: J. Deutch, "Update of the 2003 MIT Future of Nuclear Power"). • Kosten für alternative Erzeugungstechnologien: Abgeleitet aus einem aktuellen Artikel von Nicholson (Ref. 15: M. Nicholson, "How carbon pricing changes the relative competitiveness of low-carbon baseload generating technologies," 2010). Schätzungen oder Prognosen: • Gesamtkapitalkosten: Der geschätzte Bereich von $4 Mrd. bis $6 Mrd. ist eine pre-konzeptionelle Designschätzung. • Kostenreduktionen durch Lernkurven: Prognosen für Kostenreduktionen aufgrund von "manufacturing learning" für Lasersystemkomponenten, basierend auf NIF-Erfahrungen. • Nicht-Brennstoff-Betriebs-, Wartungs- und inkrementelle Kapitalkosten (O&M): Werden als Prozentsätze der gesamten Anlagenkapitalkosten angenommen und aus dem 2009 MIT-Bericht zur Zukunft der Kernkraft abgeleitet [19, Ref. 12]. • Kosten für CO2-Emissionen: Ein zugewiesener Wert von $100/MT ist ein Wert, der in politischen Diskussionen üblich ist. • Sensitivitätsparameter: Die Identifizierung von Fusionskammer-Strukturmaterial, Fusionszielkosten und Zieleffizienz als die "most highly leveraged economic parameters" basiert auf einer Monte-Carlo-Sensitivitätsanalyse, die wiederum auf Schätzungen beruht. 3. Falls externe Quellen für die Modell- und Kostenannahmen verwendet wurden – wurden diese modifiziert? Falls ja, wie? Ja, externe Quellen und Empfehlungen wurden modifiziert, skaliert oder angepasst: • LIFE-Konzept: Die Literatur beschreibt sowohl ein reines Fusions-LIFE-Konzept als auch eine Fusions-Spaltungs-Variante. Dieses Paper "deals exclusively with the pure fusion concept". Dies ist eine Modifikation/Auswahl des Anwendungsbereichs. • Lasersystemkosten: Die Lasersystemkosten werden zwar aus Lieferantenangeboten und NIF-Daten abgeleitet, es werden aber "cost reductions due to manufacturing learning" angewendet. Dies ist eine Anpassung der Rohdaten. • Kosten für Fusionsreaktor, Tritiumanlage und Energieumwandlungssysteme: Diese Kosten werden aus Literaturstudien entnommen und "scaled to the LIFE operating point using standard scaling relations". Dies ist eine direkte Modifikation durch Skalierung. • Nicht-Brennstoff-O&M und inkrementelle Kapitalkosten: Werden als Prozentsätze der gesamten Anlagenkapitalkosten angenommen, wobei diese Prozentsätze aus dem MIT-Bericht abgeleitet wurden. Hier wird die Methode der prozentualen Skalierung aus einer externen Quelle angewendet. 4. Wie lautet die Annahme zu Lernraten? Die Studie geht davon aus, dass es für die Komponenten des Lasersystems Kostenreduktionen aufgrund von "manufacturing learning" geben wird. Die verwendeten Lernraten wurden durch "experience with NIF" informiert. Spezifische prozentuale Lernraten werden in diesem Dokument jedoch nicht angegeben. 5. Wie wurden die Annahmen zu den Lernraten hergeleitet bzw. von wo stammen diese Annahmen? Die Annahmen zu den Lernraten wurden aus Erfahrungen mit dem NIF-Projekt hergeleitet. Der Kontext ist, dass viele der Lasersystemkomponenten in großen Mengen produziert werden, was die Anwendung von Lernkurven zur Schätzung von Kostenreduktionen rechtfertigt. Die Studie geht implizit davon aus, dass eine Industrie aufgebaut wird, die von Skaleneffekten und Lernkurven profitiert. 6. Wird offengelegt, ob die Kostenabschätzung auf einem Bottom-up-, Top-down- oder hybriden Ansatz basiert? Ja, es wird offengelegt, dass ein hybrider Ansatz verwendet wird: • Die Lasersystemkosten werden explizit "using a bottom up methodology" geschätzt. • Die Kosten für den Fusionsreaktor, die Tritiumanlage und die Energieumwandlungssysteme werden "from studies in the literature and scaled to the LIFE operating point using standard scaling relations" entnommen. Dies ist eher ein Top-down- oder analoger Skalierungsansatz. • Insgesamt ist es also eine Kombination aus Bottom-up (Laser) und Top-down/Analog-Skalierung (andere Systeme). 7. Beruht die Kostenherleitung auf physikalischen und technologischen Werten? Ja, die Kostenherleitung beruht maßgeblich auf physikalischen und technologischen Werten: • Lasersystemkosten: Basieren auf Lieferantenangeboten und NIF-Projektdaten, die die spezifische Lasertechnologie widerspiegeln. • Skalierung der Fusionssysteme: Die Kosten für den Fusionsreaktor, die Tritiumanlage und die Energieumwandlungssysteme werden auf den "LIFE operating point" skaliert. Dieser Betriebspunkt ist durch physikalische und technologische Parameter definiert, wie Laserenergie, Wiederholungsrate, Fusionsausbeute, Target-Gewinn, Fusionsleistung, Wirkungsgrade, Material der ersten Wand und Neutronenlast. • Fusionszielkosten: Stammen aus einer Studie zur Zielherstellung [19, Ref. 11], die die Technologie und den Prozess der Fusionszielproduktion bewertet. • Anlagenverfügbarkeit: Die hohe Verfügbarkeit (92 %) wird durch die modulare Architektur des Anlagendesigns ermöglicht. Dies ist eine technologische Entscheidung mit direkter wirtschaftlicher Auswirkung. • Wichtige Kostentreiber: Die Monte-Carlo-Sensitivitätsanalyse identifiziert das Fusionskammer-Strukturmaterial, die Fusionszielkosten und die Zieleffizienz als die wirtschaftlich wichtigsten Parameter. Dies sind alles direkte physikalische und technologische Eigenschaften und Leistungen des LIFE-Systems. 8. Werden Materialkosten und Komponentenkosten separat ausgewiesen? In der vorliegenden Quelle werden Materialkosten und Komponentenkosten nicht in detaillierten Tabellen separat ausgewiesen, wie es beispielsweise in einigen anderen Studien (z.B. STARFIRE aus unserer früheren Konversation) der Fall ist. Die Studie erwähnt: • "Laser system costs are estimated using a bottom up methodology. Unit costs are derived from vendor quotes and data from the NIF project". Hier sind die "Unit costs" wahrscheinlich integrierte Komponentenkosten. • Das Fusionskammer-Strukturmaterial wird als wichtigster wirtschaftlicher Parameter genannt, was auf Materialkosten hindeutet. • Die Fusionszielkosten werden als weitere wichtige Parameter genannt, was die Kosten des verbrauchten "Materials" oder der "Komponente" (des Targets) darstellt. Es gibt keine detaillierten Aufschlüsselungen nach Masse, Kosten pro kg oder Materialtyp in dieser Quelle. 9. Bezieht sich die Studie auf ein Energiesystem (z. B. Integration, Vergleich mit anderen Technologien) oder ist sie rein bezogen auf die Kosten des Kraftwerks und des Reaktors? Die Studie bezieht sich eindeutig auf ein umfassendes Energiesystem und geht weit über eine reine Kostenanalyse des Kraftwerks und des Reaktors hinaus. • Quantifizierung der Vorteile: Die Studie quantifiziert die Vorteile von Fusionsenergie im Hinblick auf die Vermeidung von Kohlenstoffemissionen, Atommüll und Plutoniumproduktion innerhalb des US-Stromerzeugungssystems. • Relevanz für den Energiemarkt: Sie adressiert den Bedarf an kohlenstoffarmer Grundlaststromerzeugung, der durch das Alter der bestehenden Kraftwerke und den steigenden Strombedarf entsteht. • Wirtschaftliche Wettbewerbsfähigkeit: Die Studie bewertet, ob Fusionsenergie "competitive with other low-carbon energy sources" sein kann. Sie vergleicht die Stromgestehungskosten (COE) von LIFE mit anderen Grundlast-Energiequellen und fossilen Brennstoffen (unter Berücksichtigung von Kohlenstoffkosten). • Marktdurchdringung: Es wird die Rate der Marktdurchdringung von Fusion analysiert, die durch Nachfrage und den Aufbau der Lieferkette begrenzt ist. • Politische Implikationen: Es wird ein Wert von $100/MT für CO2-Emissionen angenommen, der in politischen Diskussionen relevant ist. Die Studie diskutiert auch Proliferationsbedenken im Zusammenhang mit Plutoniumlagerung. • Gesamtwirtschaftliche Bedeutung: Die Studie bewertet die "Benefits of Early Commercialization of Fusion Energy" und die "Implications for national and global security and environment". 10. Welche Kostenreduktionspotenziale oder wirtschaftlichen Optimierungsansätze werden thematisiert? Die Studie thematisiert mehrere Kostenreduktionspotenziale und wirtschaftliche Optimierungsansätze: • Economies of Scale: Es gibt eine natürliche Größenvorteil (economy of scale) bei LIFE, da die Effizienz der Umwandlung von Laserenergie in Fusionsenergie steigt, wenn das Kraftwerk auf eine größere elektrische Leistung skaliert wird. Dies führt zu einer reduzierten Kapitalintensität ($/kW) für größere Anlagen. Dies motiviert das Design größerer Anlagen. • Verbesserungen der Zieleffizienz: Es wird erwartet, dass es "additional improvements in target efficiency" geben wird, die zur Kostenreduktion beitragen. • Niedrigere Fusionszielkosten: Die Prognose von "lower fusion target costs" ist ein weiteres Potenzial zur Kostenreduktion. • Höhere Betriebstemperaturen: Projekte von "higher operating temperatures" werden als Kostenoptimierung und Effizienzsteigerung gesehen. • Fertigungslernen (Manufacturing Learning): Es werden Kostenreduktionen aufgrund von Fertigungslernen für Lasersystemkomponenten erwartet, da diese in großen Mengen produziert werden. • Modulare Architektur: Die modulare Architektur der Anlage ermöglicht eine hohe Verfügbarkeit (92 %), was ein Schlüsselfaktor für niedrige Stromgestehungskosten ist. • Entwicklung fortschrittlicher Materialien: Die Entwicklung und Qualifizierung von Oxid-Dispersions-gehärtetem Stahl (ODS-Stahl) ermöglicht höhere Temperaturen und Leistungsdichten, was die Wirtschaftlichkeit verbessert. • Parallele Entwicklung: Die Target-Entwicklung kann parallel zu anderen Entwicklungsaktivitäten durchgeführt werden, wobei Fortschritte durch Tests an der NIF validiert werden können. Dies beschleunigt die Entwicklung und reduziert Risiken. • Maximale Nutzung bestehender Technologie: Für die Demonstrationsanlage LIFE.1 wird die maximale Nutzung bestehender Materialien und Prozesse vorgeschlagen, um den F&E-Bedarf zu minimieren. 11. Was sind die signifikantesten Kostentreiber und ökonomischen Herausforderungen laut Studie? Die Studie identifiziert die folgenden signifikantesten Kostentreiber und ökonomischen Herausforderungen, insbesondere durch ihre Sensitivitätsanalyse: • Fusionskammer-Strukturmaterial: Dies ist der "most highly leveraged economic parameter" (der am stärksten wirkende Wirtschaftsparameter). Dies unterstreicht die Herausforderung und die Bedeutung der laufenden Entwicklungen bei Materialien wie ODS-Stahl, um höhere Temperaturen und Strahlungsbeständigkeit zu erreichen. • Fusionszielkosten und Zieleffizienz: Diese beiden sind die "next two most highly leveraged parameters". Die Kosten für die Herstellung der Fusionsziele und deren Effizienz bei der Energieerzeugung sind entscheidend für die Wirtschaftlichkeit. • Pre-konzeptionelles Designniveau: Die aktuellen Kostenschätzungen basieren auf einem "pre-conceptual design level", was bedeutet, dass noch "additional work is needed". Dies impliziert, dass Unsicherheiten und potenzielle Kostensteigerungen im weiteren Designprozess bestehen. • Technisches Risiko und aggressiver Zeitplan: Der vorgeschlagene Kommerzialisierungsansatz birgt "technical risk and is aggressive". Dies stellt eine Herausforderung dar, die einen nationalen Konsens und die Zusammenarbeit von Industrie, Forschungseinrichtungen, Regierung und Aufsichtsbehörden erfordert. • Kapazitätsaufbau der Lieferkette: Die Rate der Marktdurchdringung von Fusion wird durch den "ramp up of the supply chain needed to build fusion plants" begrenzt, was eine logistische und wirtschaftliche Herausforderung darstellt. • Verpasste Marktopportunitäten: Die Studie betont die Dringlichkeit der Frühkommerzialisierung. Wenn die Recapitalisierung des Stromnetzes ohne Fusion abgeschlossen ist, sind die Marktchancen auf die Deckung des steigenden Strombedarfs begrenzt, was die potenziellen Vorteile der Fusion erheblich verringert. Dies ist eine ökonomische Herausforderung im Hinblick auf den "Window of Opportunity". | X4: Basierend auf der LIFE-Studie von Anklam et al. (2011) wird ein Vergleich mit den Kosten anderer Energieerzeugungen durchgeführt, und es lassen sich folgende Ergebnisse festhalten: **Vergleich mit anderen Energieerzeugungen:** 1. **Verglichene Technologien:** * Die Stromgestehungskosten (Cost of Electricity, COE) von LIFE werden mit denen **anderer kohlenstoffarmer Stromerzeugungstechnologien ("other low-carbon electrical energy technologies")** verglichen. * Des Weiteren erfolgt ein Vergleich mit **anderen Grundlastenergiequellen ("other base load energy sources")**. * Schließlich werden die Kosten auch mit **fossiler Stromerzeugung ("fossil fuel generation")** verglichen, wobei hier ein variabler **CO2-Preis ("cost of carbon")** berücksichtigt wird. * Die Kosten für diese alternativen Technologien wurden aus einem aktuellen Papier von Nicholson abgeleitet [20, Ref. 15]. 2. **Ergebnis des Vergleichs:** * Die geschätzten Stromgestehungskosten für **LIFE sind vergleichbar ("comparable") mit denen anderer kohlenstoffarmer Grundlastenergiequellen**. * Die Kosten für LIFE sind **geringer ("less than") als die Kosten der fossilen Stromerzeugung, wenn die CO2-Kosten 50 bis 100 US-Dollar pro Tonne (MT) übersteigen**. **Kontext der LIFE-Kosten:** * Die geschätzten Stromgestehungskosten für LIFE umfassen eine Bandbreite: Das **obere Ende** der angegebenen Spanne bezieht sich auf die **LIFE.1-Anlage (First-of-a-Kind)**, während das **untere Ende** der Spanne dem **LIFE.3-System** (repräsentiert eine ausgereifte LIFE-Technologie) entspricht. * Es wird betont, dass die LIFE-Kosten auf einem **vorkonzeptionellen Design ("pre-conceptual design")** basieren, die Ergebnisse aber indikativ sind und das wirtschaftliche Potenzial der LIFE-Technologie aufzeigen. * Die Studie kommt zu dem Schluss, dass die **Wirtschaftlichkeit von LIFE gut mit der anderer kohlenstoffarmer Technologien vergleichbar ist**. Dieser Vergleich wird visuell in **Abbildung 4 ("Economic comparison to other low carbon technologies")** dargestellt. | Y4: n/a
A5: 2 | B5: LIFE2 | C5: Inertia | D5: Indirect Drive | E5: 2200 | F5: Capital Cost | G5: NOAK | H5: Absolute | I5: =(6000000000+4000000000)/2 -> 5000000000 | J5: USD | K5: 2011 | L5: Anklam et al. (2011) | O5: Average value between 4 and 6 billion USD; Learning rates based on experiences from NIF but not further specified | P5: 0.92 | Q5: Steady-State (possible due to high repetition rate of laser pulses (nearly 15 per second)) | R5: - | S5: - | T5: -
A6: 3 | B6: LIFE3 | C6: Inertia | D6: Indirect Drive | E6: 2660 | F6: Capital Cost | G6: 10th-OAK | H6: Absolute | I6: 4000000000 | J6: USD | K6: 2011 | L6: Anklam et al. (2011) | O6: Learning rates based on experiences from NIF but not further specified | P6: 0.92 | Q6: Steady-State (possible due to high repetition rate of laser pulses (nearly 15 per second)) | R6: - | S6: - | T6: -
A7: 176 | B7: PPCS-A | C7: Magnetic | D7: Tokamak | E7: 1546 | F7: Capital Cost | G7: 10th-OAK | H7: Relative | I7: 6400 | J7: EUR/kW | K7: 2005 | L7: Ward / in Maisonnier et al. (2005) | O7: 6% discount rate; 40 years lifetime; Abgelesen; Fusion power: 5 GW; 10th of a kind plant with a corresponding cost reduction factor of 0.65 for fusion specific items; based on conventional superconducting technology, Nb3Sn for the toroidal field and NbTi for the poloidal field. Advances in superconductors, to lower cost materials and to high temperature superconductors are expected to reduce these costs but this is an uncertain issue; Divertor every 2 years; Blanket every 5 years replacement | P7: 0.75 | Q7: Steady-State with possibility for load-following by decrasing el. Output up to 50% ("Both from the plasma physics and technology viewpoints, it would be feasible to reduce the electrical output by about fifty percent.") | R7: - | S7: - | T7: - | V7: Report too long advanced conceptual Tokamak fusion power reactor | W7: Die Beantwortung der folgenden Fragen basiert ausschließlich auf der Studie zum **UWMAK-III Conceptual Tokamak Fusion Power Reactor** von Conn und Kuo (1976). --- ### 1. Welche Modellannahmen werden getroffen? Die Modellannahmen betreffen hauptsächlich die Extrapolation der Technologie und die Spezifikationen des Reaktors und des Energieumwandlungssystems: * **Technologische Extrapolation:** Design-Entscheidungen stellen **"vernünftige Extrapolationen der gegenwärtigen Technologie"** dar, die im Kontext des **"allgemeinen Zeitrahmens, der für die breite praktische Anwendung der kontrollierten Fusion vorgesehen ist"**, getroffen werden. * **Strukturmaterial:** Als primäres Strukturmaterial wird die Molybdän-basierte Legierung **TZM** (Titan-Zirkonium-Molybdän) gewählt. * **Magnete:** Die Toroidalfeldmagnete verwenden den Supraleiter **NbTi** mit **Aluminium (Al)** als Stabilisator und einer hochfesten Aluminiumlegierung als Strukturmaterial. * **Betriebsleistung:** Der Reaktor ist darauf ausgelegt, kontinuierlich **$4735 \text{ MW(th)}$** und **$1985 \text{ MW(e)}$ netto** zu erzeugen. Die angestrebte Nettoanlageneffizienz beträgt **$41.9\text{ \%}$** (Ziel: ca. $40\text{ \%}$). * **Pulsbetrieb:** Es wird angenommen, dass der Tokamak ein **gepulstes Plasma-Gerät** ist. Der Zyklus besteht aus einer Brennzeit von **$1800 \text{ Sekunden}$** und einer Auszeit von $\text{100 Sekunden}$ (Start-up, Shutdown, Pumpout/Refill), was zu einem Duty Factor von **$0.947$** führt. * **Kontinuierlicher Betrieb:** Aufgrund des gepulsten Betriebs ist die Verwendung eines **thermischen Energiespeichers** (*thermal storage*) erforderlich, um eine unterbrechungsfreie, konstante elektrische Leistung zu liefern. * **Blanket-Design:** Das Design besteht aus einer **zwei Zonen** (*two-zone*) Blanketanordnung (heliumgekühlte innere Zone als Schild, lithiumgekühlte äußere Zone zur Tritiumzucht). Die Lebensdauer der inneren Strukturwand ist auf **Anlagenlebensdauer** ausgelegt, die äußere Wand muss aufgrund der Strahlenbelastung **periodisch ersetzt** werden (geschätzte Lebensdauer: **ca. 2 Jahre**). * **Kühlmittelbedingungen:** Die Turbine Inlet Temperature (TIT) wird auf **$871^\circ\text{C}$ ($1600^\circ\text{F}$)** festgelegt, basierend auf den prognostizierten Blanket-Fähigkeiten. Der Turbineneinlassdruck beträgt **$1000 \text{ psia}$**. ### 2. Welche Modell- und Kostenannahmen basieren auf tatsächlichen Erfahrungswerten und welche nur Schätzungen oder Prognosen? Welche Annahmen stammen woher? Die Studie kombiniert bekannte Technologie mit notwendigen Extrapolationen: | Annahme | Basis (Erfahrung/Prognose) | Herkunft/Bezug | | :--- | :--- | :--- | | **Materialwahl (TZM)** | **Prognose/Extrapolation:** Basierend auf der gewünschten **hohen Betriebstemperatur** und der erwarteten Kompatibilität mit Helium und flüssigem Lithium. | Wird als "vernünftige Extrapolation der gegenwärtigen Technologie" gewählt. | | **Turbineneinlasstemperatur** | **Prognose/Extrapolation:** Die gewählte $\text{TIT}$ ($871^\circ\text{C}$) liegt **über dem damaligen Stand der Technik** ($760^\circ\text{C}$ bis $815^\circ\text{C}$). Man erwartet, dass die Temperatur bis zum Jahr 2010 um $300\text{–}400^\circ\text{C}$ steigen wird. Die Wahl basiert auf **"projizierten Blanket-Fähigkeiten"**. | Interne Systemanalyse und externe Entwicklungsprognosen. | | **Magnet-Stabilisator (Al)** | **Prognose/Extrapolation:** Die Verwendung von reinem $\text{Aluminium}$ reduziert die notwendige Stabilisatormenge um den Faktor $2$ bis $5$ im Vergleich zu Kupfer. Dies beruht auf Experimenten der University of Wisconsin, die zeigten, dass verstärktes $\text{Al}$ seine niedrige Resistivität auch unter Stress behält. | University of Wisconsin-Experimente. | | **Geschlossener Gaskreislauf** | **Erfahrung/Basis:** Das Design des **Regenerators** (88 \% Effektivität) basiert auf der Nutzung der **Leistungs- und Kostenmerkmale von Komponenten- und Designstudien** für $100\text{–}600 \text{ MW(e)}$ geschlossene Gasturbinen-Systeme. Die Turbomaschinen-Auslegung basiert auf **"vergangenen Erfahrungen"** (*past experience*). | Vergangene Studien von $100\text{–}600 \text{ MW(e)}$-Anlagen. | ### 3. Falls externe Quellen für die Modell- und Kostenannahmen verwendet wurden – wurden diese modifiziert? Falls ja, wie? Die gesamte konzeptionelle Designstudie ist eine **Modifikation und Extrapolation** vorhandener Daten und Technologien, um ein höheres Leistungsniveau zu erreichen: * **Modifikation der Design-Parameter:** Die Betriebsparameter der Helium-Gasturbine (Temperatur, Druck, Druckverhältnis, Regenerator-Effektivität) wurden **nicht direkt** übernommen, sondern durch **parametrische Analysen** und **Trade-off-Studien** zwischen Effizienz und Kosten ermittelt. * **Anpassung des Kreislaufs:** Die Komplexität des Tokamak-Designs (gepulster Betrieb, Zwei-Zonen-Blanket, Tritiumzucht) erforderte die Entwicklung eines komplexen Integrationsschemas (z. B. drei separate Kreisläufe, Zwischenwärmetauscher für Tritiumeindämmung). Die Referenzkonfiguration (mit einer Zwischenkühlstufe und Regeneration) wurde aus sechs Kandidaten ausgewählt, um die spezifischen $\text{UWMAK-III}$-Anforderungen zu erfüllen. * **Größenänderung:** Die Anlage ist eine **"wesentlich reduzierte Größe"** im Vergleich zu den Vorgängerstudien $\text{UWMAK-I}$ und $\text{UWMAK-II}$ (Hauptradius von 13 m auf 8.1 m), ermöglicht durch die Erhöhung der Neutronenwandbelastung und die Nutzung von nicht-zirkulärem Plasma. ### 4. Wie lautet die Annahme zu Lernraten? Die vorliegende Quelle **nennt keine spezifischen Zahlenwerte** für Lernraten, Lernkurven oder Produktionslernen, wie sie in den Konzepten $\text{10th-OAK}$ oder $\text{Mature NOAK}$ verwendet werden. Der Fokus liegt auf den Kapitalkosten ($\text{\$/kW}$) des gesamten Kraftwerks als Hauptziel. ### 5. Wie wurden die Annahmen zu den Lernraten hergeleitet bzw. von wo stammen diese Annahmen? Da die Quelle keine expliziten Lernraten nennt, kann diese Frage nicht beantwortet werden. ### 6. Wird offengelegt, ob die Kostenabschätzung auf einem Bottom-up-, Top-down- oder hybriden Ansatz basiert? Die Studie **offenbart nicht** explizit, ob ein Bottom-up-, Top-down- oder hybrider Ansatz verwendet wird. Die Methodik ist jedoch stark **Bottom-up-orientiert**: Es werden die **physikalischen Zwänge** des Reaktors (Temperatur, Leistung, Kühlung) als Input verwendet, um die **geforderten Spezifikationen und Dimensionen** der Hauptkomponenten (Turbinen, Wärmetauscher, Rohre) zu definieren. Anschließend wird die **Kapitalkosten der gesamten Anlage ($\text{\$/kW}$)** als wichtigstes Kriterium genannt. ### 7. Beruht die Kostenherleitung auf physikalischen und technologischen Werten? **Ja**, die gesamte ökonomische Analyse und die Auslegung beruhen auf physikalischen und technologischen Werten und Zwängen: * **Effizienz vs. Kosten:** Die Auswahl der Betriebsparameter (Druckverhältnis, Regeneration) erfolgt durch **Trade-offs zwischen thermischer Effizienz und der Komplexität/Kosten** der Komponenten. * **Physische Beschränkungen:** Die **Turbineneinlasstemperatur** (*Turbine Inlet Temperature*) ist die wichtigste ökonomische Variable, wird jedoch durch die **Temperaturfähigkeit des Blankets** (*blanket capability*) begrenzt. * **Kompaktbauweise vs. Druck:** Ein **höherer Turbineneinlassdruck** ist wünschenswert, um **kleinere Anlagenteile** und bessere Wärmeübergangskoeffizienten zu erhalten. Der gewählte Druck von $1000 \text{ psia}$ war für die geplante $\text{500–600 MW(e)}$ Turbomaschinenkapazität **zwingend erforderlich**. ### 8. Werden Materialkosten und Komponentenkosten separat ausgewiesen? **Nein.** Die Studie enthält **keine detaillierte Aufschlüsselung** von Materialkosten oder Gesamtkomponentenkosten. Sie konzentriert sich auf die **relative Optimierung** des Kreislaufs und darauf, dass die **Kapitalkosten der gesamten Anlage ($\text{\$/kW}$) der wichtigste Faktor** sind. Es werden jedoch Designentscheidungen getroffen, die auf impliziten Kostenannahmen beruhen, wie die Verwendung von **Aluminium** anstelle von Kupfer als Magnetstabilisator, um die benötigte Materialmenge zu reduzieren und das Gewicht zu senken. ### 9. Bezieht sich die Studie auf ein Energiesystem (z. B. Integration, Vergleich mit anderen Technologien) oder ist sie rein bezogen auf die Kosten des Kraftwerks und des Reaktors? Die Studie bezieht sich primär auf den **Reaktor (Tokamak) und das angeschlossene Kraftwerkssystem** (insbesondere das Helium-Gasturbinen-System). Sie berücksichtigt jedoch Randbedingungen der **Systemintegration** und des **zukünftigen Energiemarktes**: * **Umwelt- und Systemintegration:** Das Design berücksichtigt, dass die **Trockenkühlung** (*dry cooling*) für die Abwärmeabfuhr möglicherweise zwingend erforderlich sein wird. Das geschlossene Gasturbinensystem ist dafür **ökonomisch besser anpassbar** als ein Dampfkraftwerk. Es muss auch **kompatibel** mit bestehenden Stromnetzen (3600 U/min, $60 \text{ Hertz}$) sein. * **Technologievergleich:** Die Autoren erwarten, dass technologische Fortschritte im geschlossenen Helium-Gasturbinen-System, die für Fusion entwickelt wurden, direkt auf die **zukünftige Energieerzeugung** durch **fossile, Spalt- und Solaranlagen** anwendbar sein werden. Die Effizienz ($\text{41.9 \%}$) wird explizit mit früheren Fusionsanlagen ($\text{UWMAK-I}$, $\text{UWMAK-II}$, Princeton) verglichen. ### 10. Welche Kostenreduktionspotenziale oder wirtschaftlichen Optimierungsansätze werden thematisiert? Folgende Ansätze zur Kostenreduzierung werden verfolgt oder thematisiert: * **Skalierung und Standardisierung:** Verwendung von **drei identischen $585 \text{ MW(e)}$ Leistungsumwandlungsschleifen** (*three identical loops*), was die Komponentenkosten senken und die Wartung vereinfachen soll. * **Kompakte Bauweise:** Signifikante **Größenreduzierung** des Kerns (von 13 m auf 8.1 m Hauptradius) durch nicht-zirkuläres Plasma und höhere Wandbelastung. * **Erhöhte Effizienz:** Erhöhung der **thermischen Gesamteffizienz** auf $41.9\text{ \%}$ durch die Verwendung von $\text{TZM}$ für höhere Betriebstemperaturen. * **Minimierung der Komplexität:** Die $\text{TZM}$-Konstruktion des inneren Blankets ist auf **Anlagenlebensdauer** ausgelegt, um die Notwendigkeit eines Austauschs in diesem schwer zugänglichen Bereich zu eliminieren. * **Gezielter Materialeinsatz:** Nutzung von **Aluminium** für die Magnetstruktur zur Gewichtsreduzierung (auf etwa ein Drittel des Gewichts von 316 Edelstahl) und Kostensenkung. ### 11. Was sind die signifikantesten Kostentreiber und ökonomischen Herausforderungen laut Studie? Die signifikantesten ökonomischen Herausforderungen sind: * **Kapitalkosten:** Die **Kapitalkosten der gesamten Kraftwerksanlage ($\text{\$/kW}$)** sind das wichtigste Entscheidungskriterium. * **Blanket-Temperatur als Limit:** Die **Temperaturfähigkeit des Blanket-Materials** ist der begrenzende Faktor für die gesamte Anlagenleistung und Effizienz, nicht die Gasturbinen-Technologie. * **Thermische Energiespeicherung:** Die inhärent **gepulste Natur des Tokamaks** macht die Entwicklung eines **funktionsfähigen Energiespeichersystems** (*viable energy storage system*) zur Gewährleistung des kontinuierlichen Betriebs **zwingend erforderlich**. Das Versagen, ein solches System zu entwickeln, könnte die Implementierung der Anlage **behindern**. * **Komplexität und Tritiumeindämmung:** Die Notwendigkeit eines **Zwischenwärmetauschers** aufgrund der Tritiumzucht im Lithium-Blanket führt zu einer **niedrigeren Turbineneinlasstemperatur** und damit zu einer reduzierten Effizienz und erhöhter Komplexität. * **Wartung des Divertors und des Blankets:** Das Divertor-Auffangblech (*sacrificial wall*) und die äußere Blankethülle müssen **häufig ausgetauscht** werden (z. B. Divertorblech alle 17 Stunden, äußere Blanketwand alle 2 Jahre), was die Wartungskosten erhöht. | X7: Die Kostenvergleiche der Fusionsreaktoren mit anderen Energieerzeugungstechnologien, die in den Quellen diskutiert werden (sowohl in der neuen Quelle als auch in der Gesprächshistorie), führen im Allgemeinen zu dem Ergebnis, dass **Fusionsenergie nur dann wettbewerbsfähig** ist, wenn **zukünftige, optimierte (10th-OAK oder Mature NOAK) Designs** realisiert werden, die auf **zukünftigen Projektionen** von Kosten und technologischem Fortschritt basieren. ### 1. Ergebnis des Kostenvergleichs Die Ergebnisse des Vergleichs sind nur dann positiv, wenn die Fusionsdesigns stark optimiert sind und von Lernkurven profitieren: | Reaktorkonzept / Studie | Ergebnis des Vergleichs | Vergleichsbasis | | :--- | :--- | :--- | | **UWMAK-III (1976)** | Der Fokus lag auf der **internen Optimierung** des $\text{\$/kW}$-Kapitalkostenziels und der Effizienz (Nettoeffizienz 41,9 \%). Es wurde **keine direkte quantitative Kostenvergleichsaussage** mit fossilen oder Spaltkraftwerken getroffen. Die Studie erwartet, dass die technologischen Fortschritte, die für die Helium-Gasturbinen benötigt werden, auch in zukünftigen fossilen, Spalt- und Solaranlagen zur Anwendung kommen. | Zukünftige Technologie | | **Helsley and Burke (2014)** | Ein voll ausgelastetes **großes HIF-System** (30+ $\text{GWe}$) wäre **wirtschaftlich tragfähig** (*economically viable*) und könnte Energie zu **etwa der Hälfte der Kosten** (*roughly one half the cost*) der derzeitigen konventionellen fossilen oder Spalt-Systeme produzieren. | Aktuelle konventionelle Kosten | | **Lerede et al. (2023)** | Fusionsanlagen können nur **durch einen robusten Lernprozess** und die Entwicklung zu **"reifen Fusionskraftwerken"** (*mature fusion power plants*) mit **anderen kohlenstoffarmen Infrastrukturen wie modernen Leichtwasserreaktoren konkurrieren** [Lerede et al. (2023)]. | Zukünftige kohlenstoffarme Alternativen | | **Prometheus (Moir, 1992)** | Erreichte ein niedriges Stromgestehungspreis (COE) von **62,6 bis 72,0 mills/kWh** (1991$) und erfüllte damit die **niedrigeren kommerziellen Ziele** [Moir (1992)]. | Kommerzielle Ziele | ### 2. Vergleich mit historischen oder zukunftsgerichteten Projektionen Alle Fusionsstudien, die die Kosten mit externen Energiequellen vergleichen, stützen sich **fast ausschließlich auf zukunftsgerichtete Projektionen** und **hochgerechnete Werte** für die Fusionsanlage. * **Extrapolation der Technologie:** Das $\text{UWMAK-III}$-Design basiert auf **"vernünftigen Extrapolationen der gegenwärtigen Technologie"** (*reasonable extrapolations of present technology*). Die maximal zulässige Turbineneintrittstemperatur ($871^\circ\text{C}$ / $1600^\circ\text{F}$) wurde gewählt, basierend auf den erwarteten **zukünftigen Entwicklungen** in der Blankettstruktur. Die Technologie wird im Kontext des **"allgemeinen Zeitrahmens, der für die breite praktische Anwendung der kontrollierten Fusion vorgesehen ist"**, betrachtet. * **Wettbewerb des zukünftigen Marktes:** Studien wie die von Krakowski (1995) analysieren die Richtung für **"wettbewerbsfähige MFE-Kraftwerke"** (*competitive MFE power plants*), die einen **zukünftigen Marktzug** (*future market pull*) aufweisen müssen, und vergleichen die Kosten der Fusionsanlagen in ihrer **"reifen Technologie"**-Phase ($10\text{th-OAK}$ oder $\text{100th-OAK}$) [Krakowski (1995)]. * **Lernkurvenannahmen:** Die ökonomische Wettbewerbsfähigkeit in Studien wie Lerede et al. (2023) hängt von einer angenommenen **Kostenreduzierung** durch technologisches Lernen (z. B. 30 % Kapitalminderung für die $\text{10th-OAK}$) ab [Lerede et al. (2023)]. * **Extrapolation des Zeitrahmens:** Die Prometheus-Studien (Moir, 1992) beruhen auf einer Extrapolation der Physik, Technologie und Ökonomie um **etwa 30 bis 40 Jahre** [Moir (1992)]. Zusammenfassend lässt sich sagen, dass der Kostenvergleich nicht mit den historischen, heutigen Kosten von Fusionsanlagen erfolgt, sondern mit der **projektierten, optimierten COE-Leistung der zukünftigen Fusionsreaktoren** im Vergleich zu den **zukünftigen oder gegenwärtigen Kosten von Konkurrenztechnologien** (Spalt-, Solar- oder Fossil-Kraftwerke). | Y7: 25% buildings, 35% reactor plant equipment, 25% turbine plant, 12% electric plant equipment, 3% miscellaneous items (10& toroidal field magnets of reactor plant equipment)
